<?xml version="1.0" ?>
<!-- =================================================================================== -->
<!-- |    This document was autogenerated by xacro from ddr.main.xacro                 | -->
<!-- |    EDITING THIS FILE BY HAND IS NOT RECOMMENDED                                 | -->
<!-- =================================================================================== -->
<robot name="diff_drive_robot" xmlns:xacro="http://www.ros.org/wiki/xacro">
  <material name="black">
    <color rgba="0 0 0 1"/>
  </material>
  <material name="blue">
    <color rgba="0.0 0.0 0.8 1.0"/>
  </material>
  <material name="green">
    <color rgba="0.0 0.8 0.0 1.0"/>
  </material>
  <material name="grey">
    <color rgba="0.2 0.2 0.2 1.0"/>
  </material>
  <material name="orange">
    <color rgba="1.0 0.423529411765 0.0392156862745 1.0"/>
  </material>
  <material name="brown">
    <color rgba="0.870588235294 0.811764705882 0.764705882353 1.0"/>
  </material>
  <material name="red">
    <color rgba="0.8 0.0 0.0 1.0"/>
  </material>
  <material name="white">
    <color rgba="1.0 1.0 1.0 1.0"/>
  </material>
  <!-- ros_control plugin -->
  <gazebo>
    <plugin filename="libgazebo_ros_control.so" name="gazebo_ros_control">
      <robotNamespace>/ddr</robotNamespace>
      <robotSimType>gazebo_ros_control/DefaultRobotHWSim</robotSimType>
    </plugin>
  </gazebo>
  <!--
        Camera Sensor
    -->
  <gazebo reference="rgba_camera">
    <sensor name="rgba_camera_sensor" type="camera">
      <parent link="rgba_camera"/>
      <update_rate>30.0</update_rate>
      <camera name="rgba_camera_camera">
        <!--<horizontal_fov>1.3962634</horizontal_fov>-->
        <!--<image>-->
        <!--    <width>800</width>-->
        <!--    <height>800</height>-->
        <!--    <format>R8G8B8</format>-->
        <!--</image>-->
        <!--<clip>-->
        <!--    <near>0.02</near>-->
        <!--    <far>300</far>-->
        <!--</clip>-->
        <!--<noise>-->
        <!--    <type>gaussian</type>-->
        <!--    <mean>0.0</mean>-->
        <!--    <stddev>0.007</stddev>-->
        <!--</noise>-->
      </camera>
      <!--<plugin name="$camera_controller" filename="libgazebo_ros_openni_kinect.so">
                <baseline>0.2</baseline>
                <alwaysOn>true</alwaysOn>
                <updateRate>1.0</updateRate>
                <cameraName>${camera_name}_ir</cameraName>
                <imageTopicName>/${camera_name}/depth/image_raw</imageTopicName>
                <cameraInfoTopicName>/${camera_name}/depth/camera_info</cameraInfoTopicName>
                <depthImageTopicName>/${camera_name}/depth/image_raw</depthImageTopicName>
                <depthImageInfoTopicName>/${camera_name}/depth/camera_info</depthImageInfoTopicName>
                <pointCloudTopicName>/${camera_name}/depth/points</pointCloudTopicName>
                <frameName>${camera_name}_frame</frameName>
                <pointCloudCutoff>0.5</pointCloudCutoff>
                <distortionK1>0.00000001</distortionK1>
                <distortionK2>0.00000001</distortionK2>
                <distortionK3>0.00000001</distortionK3>
                <distortionT1>0.00000001</distortionT1>
                <distortionT2>0.00000001</distortionT2>
                <CxPrime>0</CxPrime>
                <Cx>0</Cx>
                <Cy>0</Cy>
                <focalLength>0</focalLength>
                <hackBaseline>0</hackBaseline>
            </plugin>-->
      <plugin filename="libgazebo_ros_camera.so" name="camera_controller">
        <alwaysOn>true</alwaysOn>
        <updateRate>0.0</updateRate>
        <cameraName>ddr/rgba_camera</cameraName>
        <imageTopicName>image_raw</imageTopicName>
        <cameraInfoTopicName>camera_info</cameraInfoTopicName>
        <frameName>rgba_camera</frameName>
        <hackBaseline>0.07</hackBaseline>
        <distortionK1>0.0</distortionK1>
        <distortionK2>0.0</distortionK2>
        <distortionK3>0.0</distortionK3>
        <distortionT1>0.0</distortionT1>
        <distortionT2>0.0</distortionT2>
      </plugin>
    </sensor>
  </gazebo>
  <!--
        Build the robot!
    -->
  <!--Base Link-->
  <link name="base_link"/>
  <gazebo reference="ddr_chassis">
    <material>Gazebo/White</material>
  </gazebo>
  <link name="ddr_chassis">
    <visual>
      <geometry>
        <cylinder length="0" radius="0"/>
      </geometry>
      <material name="white"/>
    </visual>
    <collision>
      <geometry>
        <cylinder length="0" radius="0"/>
      </geometry>
    </collision>
    <inertial>
      <mass value="0.0"/>
      <inertia ixx="0.0" ixy="0" ixz="0" iyy="0.0" iyz="0" izz="0.0"/>
    </inertial>
  </link>
  <joint name="robot_chassis_joint" type="fixed">
    <parent link="base_link"/>
    <child link="ddr_chassis"/>
    <origin xyz="0 0 0.01"/>
  </joint>
  <gazebo reference="right_wheel">
    <material>Gazebo/FlatBlack</material>
  </gazebo>
  v
        
  <link name="right_wheel">
    <visual>
      <origin rpy="0 1.571 0" xyz="0 0 0"/>
      <geometry>
        <cylinder length="0.0" radius="0"/>
      </geometry>
      <material name="black"/>
    </visual>
    <collision>
      <geometry>
        <sphere radius="0"/>
      </geometry>
    </collision>
    <inertial>
      <mass value="0.0"/>
      <inertia ixx="0.0" ixy="0" ixz="0" iyy="0.0" iyz="0" izz="0.0"/>
    </inertial>
  </link>
  <joint name="right_wheel_joint" type="continuous">
    <parent link="ddr_chassis"/>
    <child link="right_wheel"/>
    <origin xyz="0.0 0 -0.0"/>
    <axis xyz="1 0 0"/>
  </joint>
  <gazebo reference="left_wheel">
    <material>Gazebo/FlatBlack</material>
  </gazebo>
  v
        
  <link name="left_wheel">
    <visual>
      <origin rpy="0 1.571 0" xyz="0 0 0"/>
      <geometry>
        <cylinder length="0.0" radius="0"/>
      </geometry>
      <material name="black"/>
    </visual>
    <collision>
      <geometry>
        <sphere radius="0"/>
      </geometry>
    </collision>
    <inertial>
      <mass value="0.0"/>
      <inertia ixx="0.0" ixy="0" ixz="0" iyy="0.0" iyz="0" izz="0.0"/>
    </inertial>
  </link>
  <joint name="left_wheel_joint" type="continuous">
    <parent link="ddr_chassis"/>
    <child link="left_wheel"/>
    <origin xyz="0.0 0 -0.0"/>
    <axis xyz="1 0 0"/>
  </joint>
  <gazebo reference="front_glider">
    <material>Gazebo/FlatBlack</material>
  </gazebo>
  <link name="front_glider">
    <visual>
      <geometry>
        <sphere radius="0"/>
      </geometry>
      <material name="black"/>
    </visual>
    <collision>
      <geometry>
        <sphere radius="0"/>
      </geometry>
    </collision>
    <inertial>
      <mass value="0.0"/>
      <inertia ixx="0.0" ixy="0" ixz="0" iyy="0.0" iyz="0" izz="0.0"/>
    </inertial>
  </link>
  <joint name="front_glider_joint" type="fixed">
    <parent link="ddr_chassis"/>
    <child link="front_glider"/>
    <origin xyz="0 0.5 -0.09"/>
  </joint>
  <gazebo reference="back_glider">
    <material>Gazebo/FlatBlack</material>
  </gazebo>
  <link name="back_glider">
    <visual>
      <geometry>
        <sphere radius="0"/>
      </geometry>
      <material name="black"/>
    </visual>
    <collision>
      <geometry>
        <sphere radius="0"/>
      </geometry>
    </collision>
    <inertial>
      <mass value="0.0"/>
      <inertia ixx="0.0" ixy="0" ixz="0" iyy="0.0" iyz="0" izz="0.0"/>
    </inertial>
  </link>
  <joint name="back_glider_joint" type="fixed">
    <parent link="ddr_chassis"/>
    <child link="back_glider"/>
    <origin xyz="0 -0.5 -0.09"/>
  </joint>
  <gazebo reference="rgba_camera">
    <material>Gazebo/Red</material>
  </gazebo>
  <link name="rgba_camera">
    <visual>
      <geometry>
        <box size="0.2 0.1 0.2"/>
      </geometry>
      <material name="red"/>
    </visual>
    <collision>
      <geometry>
        <box size="0.2 0.1 0.2"/>
      </geometry>
    </collision>
    <inertial>
      <mass value="0.4"/>
      <inertia ixx="0.00166666666667" ixy="0" ixz="0" iyy="0.00266666666667" iyz="0" izz="0.00166666666667"/>
    </inertial>
  </link>
  <joint name="rgba_camera_joint" type="fixed">
    <parent link="ddr_chassis"/>
    <child link="rgba_camera"/>
    <origin xyz="0 0 0.1"/>
  </joint>
</robot>

