<?xml version="1.0"?>
<robot xmlns:xacro="http://www.ros.org/wiki/xacro" name="diff_drive_robot">
    
    <xacro:arg name="chassis_radius" default="0.6" />
    
    <material name="black">
        <color rgba="0 0 0 1"/>
    </material>


    <link name="base_link" />
    
    <link name="robot_chassis">
        <visual>
            <geometry>
                <cylinder length="0.2" radius="$(arg chassis_radius)"/>
            </geometry>
        </visual>
    </link>
    <joint name="robot_chassis_joint" type="fixed">
        <parent link="base_link"/>
        <child link="robot_chassis"/>
        <origin xyz="0 0 0.5"/>
    </joint>
    
    
    <link name="right_wheel">
        <visual>
            <geometry>
                <sphere radius="0.2"/>
            </geometry>
            <material name="black"/>
        </visual>
    </link>
    <joint name="right_wheel_joint" type="continuous">
        <parent link="robot_chassis"/>
        <child link="right_wheel"/>
        <origin xyz="0.35 0 -0.1"/>
        <axis xyz="1 0 0"/>
    </joint>
    
    
    <link name="left_wheel">
        <visual>
            <geometry>
                <sphere radius="0.2"/>
            </geometry>
            <material name="black"/>
        </visual>
    </link>
    <joint name="left_wheel_joint" type="continuous">
        <parent link="robot_chassis"/>
        <child link="left_wheel"/>
        <origin xyz="-0.35 0 -0.1"/>
        <axis xyz="1 0 0"/>
    </joint>
    
    
    <link name="front_roller">
        <visual>
            <geometry>
                <sphere radius="0.1" />
            </geometry>
            <material name="black"/>
        </visual>
    </link>
    <joint name="front_roller_joint" type="fixed">
        <parent link="robot_chassis"/>
        <child link="front_roller"/>
        <origin xyz="0 0.5 -0.09"/>
    </joint>
    
    
    <link name="back_roller">
        <visual>
            <geometry>
                <sphere radius="0.1" />
            </geometry>
            <material name="black"/>
        </visual>
    </link>
    <joint name="back_roller_joint" type="fixed">
        <parent link="robot_chassis"/>
        <child link="back_roller"/>
        <origin xyz="0 -0.5 -0.09"/>
    </joint>
    
</robot>